<?xml version="1.0"?>
<robot name="sous_marin">
  <link name="base_link">
    <visual>
      <origin rpy="-1.57075 0.0 0.0" xyz="0 0 0"/>
      <geometry>
        <mesh filename="package://urdf_tutorial_zo/meshes/coque_solide.dae"/>
      </geometry>
    </visual>
  </link>

    <!--Panel avant -->
  <link name="panel_avant_droit">
    <visual>
      <geometry>
        <mesh filename="package://urdf_tutorial_zo/meshes/plane.dae"/>
      </geometry>
    </visual>
  </link>

  <joint name="bras_avant_droit_joint" type="revolute">
    <axis xyz="1 0 0"/>
    <limit effort="1000.0" lower="-0.548" upper="0.548" velocity="0.5"/>
    <origin rpy="0 0.0 0" xyz="-0.115 0.177 0.181"/>
    <parent link="base_link"/>
    <child link="panel_avant_droit"/>
  </joint>

  <link name="panel_avant_gauche">
    <visual>
      <geometry>
        <mesh filename="package://urdf_tutorial_zo/meshes/plane.dae"/>
      </geometry>
    </visual>
  </link>

  <joint name="bras_avant_gauche_joint" type="revolute">
    <axis xyz="1 0 0"/>
    <limit effort="1000.0" lower="-0.548" upper="0.548" velocity="0.5"/>
    <origin rpy="0 3.14 0" xyz="0.115 0.177 0.181"/>
    <parent link="base_link"/>
    <child link="panel_avant_gauche"/>
  </joint>

  <!--Panel arriere horizontales -->

  <link name="panel_right">
    <visual>
      <geometry>
        <mesh filename="package://urdf_tutorial_zo/meshes/plane.dae"/>
      </geometry>
      <origin rpy="0 0.0 0" xyz="0 0 0.0"/>
    </visual>
  </link>

  <joint name="bras_arriere_droit_joint" type="revolute">
    <axis xyz="1 0 0"/>
    <limit effort="1000.0" lower="-0.548" upper="0.548" velocity="0.5"/>
    <origin xyz="-0.095 1.4 0.15"/>
    <parent link="base_link"/>
    <child link="panel_right"/>
  </joint>

  <link name="panel_left">
    <visual>
      <geometry>
        <mesh filename="package://urdf_tutorial_zo/meshes/plane.dae"/>
      </geometry>
      <origin rpy="0 3.14 0" xyz="0 0 0.0"/>
    </visual>
  </link>

  <joint name="bras_arriere_gauche_joint" type="revolute">
    <axis xyz="1 0 0"/>
    <limit effort="1000.0" lower="-0.548" upper="0.548" velocity="0.5"/>
    <origin xyz="0.095 1.4 0.15"/>
    <parent link="base_link"/>
    <child link="panel_left"/>
  </joint>

        <!--Panel arriere verticales -->
  <link name="panel_haut">
    <visual>
      <geometry>
        <mesh filename="package://urdf_tutorial_zo/meshes/plane.dae"/>
      </geometry>
      <origin rpy="0 0.0 0" xyz="0 0 0.0"/>
    </visual>
  </link>

  <joint name="bras_arriere_haut_joint" type="revolute">
    <axis xyz="1 0 0"/>
    <limit effort="1000.0" lower="-0.548" upper="0.548" velocity="0.5"/>
    <origin xyz="0.0 1.4 0.24" rpy ="0.0 1.57075 0.0"/>
    <parent link="base_link"/>
    <child link="panel_haut"/>
  </joint>

<link name="panel_bas">
    <visual>
      <geometry>
        <mesh filename="package://urdf_tutorial_zo/meshes/plane.dae"/>
      </geometry>
      <origin rpy="0 3.14 0" xyz="0 0 0.0"/>
    </visual>
  </link>

<joint name="bras_arriere_bas_joint" type="revolute">
    <axis xyz="1 0 0"/>
    <limit effort="1000.0" lower="-0.548" upper="0.548" velocity="0.5"/>
    <origin xyz="0.0 1.4 0.055" rpy ="0.0 1.57075 0.0"/>
    <parent link="base_link"/>
    <child link="panel_bas"/>
  </joint>



</robot>